Workbook
Name excess: #REF!
Name new: #REF!
Name OLD: #REF!
Name orig: #REF!
Name ref: #REF!

Sheet Production Plan_wk33
B1: WEEK-33 | D1: trial | F1: 46237 | I1: =F1+1 -> 46238 | L1: =I1+1 -> 46239 | O1: =L1+1 -> 46240 | R1: =O1+1 -> 46241 | U1: =R1+1 -> 46242 | X1: =U1+1 -> 46243 | AH1: compressed | AI1: 9hrs | AJ1: regular working time | AM1: 6 days work week | AO1: 7.5hrs | AP1: regular working time
D2: training | F2: Monday | I2: Tuesday | L2: Wednesday | O2: Thursday | R2: Friday | U2: Saturday | X2: Sunday | AI2: 2.25 | AJ2: max OT hrs | AO2: 3.75hrs | AP2: max OT hrs
A3: Cell number | B3: Model | C3: Part # | D3: PPH | E3: Shifting Schedule | F3: 1st | G3: 2nd | H3: 3rd | I3: 1st | J3: 2nd | K3: 3rd | L3: 1st | M3: 2nd | N3: 3rd | O3: 1st | P3: 2nd | Q3: 3rd | R3: 1st | S3: 2nd | T3: 3rd | U3: 1st | V3: 2nd | W3: 3rd | X3: 1st | Y3: 2nd | Z3: 3rd | AA3: MODEL | AB3: TOTAL | AC3: Pallet | AD3: SNP | AE3: Hours | AI3: =9+2.25 -> 11.25 | AJ3: total work hrs | AO3: =7.5+3.75 -> 11.25 | AP3: total work hrs
A4: 1 | B4: HG180 NH | C4: 656765900A nh euro | D4: 17 | AA4: HG180 NH | AB4: =SUM(F4:Z4) -> 0 | AC4: 84 | AD4: =AC4/12 -> 7 | AE4: =ROUND(IFERROR(AB4/D4,0),) -> 0 | AN4: 0.25 | AO4: snack break
A5: 1 | B5: HG180 - Heater | C5: 667947100A htr baseball | D5: 15 | AA5: HG180 H | AB5: =SUM(F5:Z5) -> 0 | AC5: 84 | AD5: =AC5/12 -> 7 | AE5: =ROUND(IFERROR(AB5/D5,0),) -> 0 | AN5: =SUM(AN1:AN4) -> 0.25 | AO5: total
A6: 1 | B6: HG180 - Heater | C6: 667947101A htr baseball | D6: 16 | AA6: HG180 H | AB6: =SUM(F6:Z6) -> 0 | AC6: 84 | AD6: =AC6/12 -> 7 | AE6: =ROUND(IFERROR(AB6/D6,0),) -> 0
A7: 1 | B7: HG180 - Heater | C7: 656766100A htr euro | D7: 15 | AA7: HG180 H | AB7: =SUM(F7:Z7) -> 0 | AC7: 84 | AD7: =AC7/12 -> 7 | AE7: =ROUND(IFERROR(AB7/D7,0),) -> 0
A8: 1 | B8: HG180 NH | C8: 656764800A baseball | D8: 18 | F8: 135 | H8: 135 | I8: 135 | K8: 135 | AA8: HG180 NH | AB8: =SUM(F8:Z8) -> 540 | AC8: 84 | AD8: =AC8/12 -> 7 | AE8: =ROUND(IFERROR(AB8/D8,0),) -> 30
A9: 1 | B9: HG180 NH | C9: 656765300A baseball | D9: 18 | L9: 135 | N9: 135 | AA9: HG180 NH | AB9: =SUM(F9:Z9) -> 270 | AC9: 84 | AD9: =AC9/12 -> 7 | AE9: =ROUND(IFERROR(AB9/D9,0),) -> 15
A10: 1 | B10: HG180 NH | C10: 658875500A artificial | D10: 17 | AA10: HG180 NH | AB10: =SUM(F10:Z10) -> 0 | AC10: 84 | AD10: =AC10/12 -> 7 | AE10: =ROUND(IFERROR(AB10/D10,0),) -> 0
A11: 1 | B11: HG182 - Heater | C11: 661413400A | D11: 15 | AA11: HG180 H | AB11: =SUM(F11:Z11) -> 0 | AC11: 84 | AD11: =AC11/12 -> 7 | AE11: =ROUND(IFERROR(AB11/D11,0),) -> 0
A12: 1 | B12: HG240 Heater | C12: 661787500A | AA12: HG180 H | AB12: =SUM(F12:Z12) -> 0 | AD12: =AC12/12 -> 0 | AE12: =ROUND(IFERROR(AB12/D12,0),) -> 0
A13: 1 | B13: THBRW NH | C13: Trial THBRW NH | AB13: =SUM(F13:Z13) -> 0 | AD13: =AC13/12 -> 0 | AE13: =ROUND(IFERROR(AB13/D13,0),) -> 0
A14: 1 | B14: THBRW H | C14: Trial THBRW H | AB14: =SUM(F14:Z14) -> 0 | AD14: =AC14/12 -> 0 | AE14: =ROUND(IFERROR(AB14/D14,0),) -> 0
A15: 2 | B15: HG180 NH | C15: 656765900A | D15: 16 | AA15: HG180 NH | AB15: =SUM(F15:Z15) -> 0 | AC15: 84 | AD15: =AC15/12 -> 7 | AE15: =ROUND(IFERROR(AB15/D15,0),) -> 0
A16: 2 | B16: HG180 NH | C16: 656765300A baseball | D16: 16 | AA16: HG180 NH | AB16: =SUM(F16:Z16) -> 0 | AC16: 84 | AD16: =AC16/12 -> 7 | AE16: =ROUND(IFERROR(AB16/D16,0),) -> 0
A17: 2 | B17: TN170 Heater | C17: 646763200G | D17: 17 | AA17: TN170 H | AB17: =SUM(F17:Z17) -> 0 | AC17: 60 | AD17: =AC17/12 -> 5 | AE17: =ROUND(IFERROR(AB17/D17,0),) -> 0
A18: 2 | B18: TN170 Heater | C18: 659434500C Dimple | D18: 9 | AA18: TN170 H | AB18: =SUM(F18:Z18) -> 0 | AC18: 60 | AD18: =AC18/12 -> 5 | AE18: =ROUND(IFERROR(AB18/D18,0),) -> 0
A19: 2 | B19: TN170 NH | C19: 659434400C Dimple | D19: 9 | AA19: TN170 NH | AB19: =SUM(F19:Z19) -> 0 | AC19: 60 | AD19: =AC19/12 -> 5 | AE19: =ROUND(IFERROR(AB19/D19,0),) -> 0
A20: 2 | B20: TN170 NH | C20: 643602400H | D20: 18 | AA20: TN170 NH | AB20: =SUM(F20:Z20) -> 0 | AC20: 60 | AD20: =AC20/12 -> 5 | AE20: =ROUND(IFERROR(AB20/D20,0),) -> 0
A21: 2 | B21: TN170 Heater | C21: 659434900C Dimple | D21: 18 | AA21: TN170 NH | AB21: =SUM(F21:Z21) -> 0 | AC21: 60 | AD21: =AC21/12 -> 5 | AE21: =ROUND(IFERROR(AB21/D21,0),) -> 0
A22: 3 | B22: TB670 Heater - BlACK thread | C22: 648541000D | D22: 17 | AA22: TB670 H | AB22: =SUM(F22:Z22) -> 0 | AC22: 84 | AD22: =AC22/12 -> 7 | AE22: =ROUND(IFERROR(AB22/D22,0),) -> 0
A23: 3 | B23: TB670 Heater - Red Thread | C23: 648541001D | D23: 17 | AA23: TB670 H | AB23: =SUM(F23:Z23) -> 0 | AC23: 84 | AD23: =AC23/12 -> 7 | AE23: =ROUND(IFERROR(AB23/D23,0),) -> 0
A24: 4 | B24: TB670 Heater (Service Kit - Black Thread) | C24: 660284300B | D24: 17 | AA24: TB670 H | AB24: =SUM(F24:Z24) -> 0 | AC24: 84 | AD24: =AC24/12 -> 7 | AE24: =ROUND(IFERROR(AB24/D24,0),) -> 0 | AF24: TB700 or TB670?
A25: 4 | B25: TB670 Heater (Service Kit - Gray Thread) | C25: 660284302B | D25: 17 | AA25: TB670 H | AB25: =SUM(F25:Z25) -> 0
A26: 4 | B26: TB670 NH Circular - black/black | C26: 660284400A | D26: 11 | AA26: TB670 C | AB26: =SUM(F26:Z26) -> 0 | AC26: 84 | AD26: =AC26/12 -> 7 | AE26: =ROUND(IFERROR(AB26/D26,0),) -> 0
A27: 4 | B27: TB670 NH Circular | C27: 648622501B | D27: 11 | AA27: TB670 C | AB27: =SUM(F27:Z27) -> 0 | AC27: 84 | AD27: =AC27/12 -> 7 | AE27: =ROUND(IFERROR(AB27/D27,0),) -> 0
A28: 4 | B28: TB670 NH Circular | C28: 648622501B | D28: 11 | AA28: TB670 C | AB28: =SUM(F28:Z28) -> 0 | AC28: 84 | AD28: =AC28/12 -> 7 | AE28: =ROUND(IFERROR(AB28/D28,0),) -> 0
A29: 4 | B29: TB670 NH Circular | C29: 648622500B | D29: 11 | AA29: TB670 C | AB29: =SUM(F29:Z29) -> 0 | AC29: 84 | AD29: =AC29/12 -> 7 | AE29: =ROUND(IFERROR(AB29/D29,0),) -> 0
A30: 4 | B30: TB670 Heater Circular | C30: 648622600C | D30: 11 | AA30: TB670 C | AB30: =SUM(F30:Z30) -> 0 | AC30: 84 | AD30: =AC30/12 -> 7 | AE30: =ROUND(IFERROR(AB30/D30,0),) -> 0
A31: 4 | B31: TB670 Heater Circular | C31: 648622601C | D31: 11 | AA31: TB670 C | AB31: =SUM(F31:Z31) -> 0 | AC31: 84 | AD31: =AC31/12 -> 7 | AE31: =ROUND(IFERROR(AB31/D31,0),) -> 0
A32: 4 | B32: TB670 Heater - Red Thread | C32: 648541001D | D32: 17 | AA32: TB670 H | AB32: =SUM(F32:Z32) -> 0 | AC32: 84 | AD32: =AC32/12 -> 7 | AE32: =ROUND(IFERROR(AB32/D32,0),) -> 0
A33: 4 | B33: TB670 Heater (Gray Thread) | C33: 648541002D | D33: 17 | AA33: TB670 H | AB33: =SUM(F33:Z33) -> 0 | AC33: 84 | AD33: =AC33/12 -> 7 | AE33: =ROUND(IFERROR(AB33/D33,0),) -> 0
A34: 4 | B34: TB670 Heater - Black thread | C34: 648541000D | D34: 17 | AA34: TB670 H | AB34: =SUM(F34:Z34) -> 0 | AC34: 84 | AD34: =AC34/12 -> 7 | AE34: =ROUND(IFERROR(AB34/D34,0),) -> 0
A35: 5 | B35: TB670 Heater - Black thread | C35: 648541000D | D35: 17 | AA35: TB670 H | AB35: =SUM(F35:Z35) -> 0 | AC35: 84 | AD35: =AC35/12 -> 7 | AE35: =ROUND(IFERROR(AB35/D35,0),) -> 0
A36: 5 | B36: TB670 Heater - Red Thread | C36: 648541001D | D36: 17 | AA36: TB670 H | AB36: =SUM(F36:Z36) -> 0 | AC36: 84 | AD36: =AC36/12 -> 7 | AE36: =ROUND(IFERROR(AB36/D36,0),) -> 0
A37: 5 | B37: TB670 Heater Circular | C37: 648622601C | D37: 9 | AA37: TB670 H | AB37: =SUM(F37:Z37) -> 0 | AC37: 84 | AD37: =AC37/12 -> 7 | AE37: =ROUND(IFERROR(AB37/D37,0),) -> 0
... A47: 8 | B47: MQ150 NH - AZP - with emboss | C47: 647528200B | D47: 14 | AA47: MQ150 NH | AB47: =SUM(F47:Z47) -> 0 | AC47: 60 | AD47: =AC47/12 -> 5 | AE47: =ROUND(IFERROR(AB47/D47,0),) -> 0
A48: 8 | B48: MQ170 Heater - AMI | C48: 654627401B | AA48: AMI | AB48: =SUM(F48:Z48) -> 0 | AC48: 60 | AD48: =AC48/12 -> 5 | AE48: =ROUND(IFERROR(AB48/D48,0),) -> 0
A49: 8 | B49: TN170 Heater | C49: 659434500B | D49: 16 | AA49: TN170 H | AB49: =SUM(F49:Z49) -> 0 | AC49: 60 | AD49: =AC49/12 -> 5 | AE49: =ROUND(IFERROR(AB49/D49,0),) -> 0
...

Sheet Body Supply
B2: Serial Production | C2: Rev. 0 | E2: Rev. 0 | F2: {='Production Plan_wk33'!F1:F1} -> 46237 | I2: =F2+1 -> 46238 | L2: =I2+1 -> 46239 | O2: =L2+1 -> 46240 | R2: =O2+1 -> 46241 | U2: =R2+1 -> 46242 | X2: =U2+1 -> 46243
D3: PU Body PN | F3: Monday | I3: Tuesday | L3: Wednesday | O3: Thursday | R3: Friday | U3: Saturday | X3: Sunday
F4: 1st | G4: 2nd | H4: 3rd | I4: 1st | J4: 2nd | K4: 3rd | L4: 1st | M4: 2nd | N4: 3rd | O4: 1st | P4: 2nd | Q4: 3rd | R4: 1st | S4: 2nd | T4: 3rd | U4: 1st | V4: 2nd | W4: 3rd | X4: 1st | Y4: 2nd | Z4: 3rd
B5: GN7 1T Heater | D5: 657040000G | E5: =SUM(F5:Z5) -> 0 | F5: 0 | G5: 0 | H5: 0 | I5: 0 | J5: 0 | K5: 0 | L5: 0 | M5: 0 | N5: 0 | O5: 0 | P5: 0 | Q5: 0 | R5: 0 | S5: 0 | T5: 0 | U5: 0 | V5: 0 | W5: 0 | X5: 0 | Y5: 0 | Z5: 0 | AA5: =E5='Production Plan_wk33'!C341 -> TRUE
B6: GN7 1T HOD | D6: 660578600E | E6: =SUM(F6:Z6) -> 0 | F6: 0 | G6: 0 | H6: 0 | I6: 0 | J6: 0 | K6: 0 | L6: 0 | M6: 0 | N6: 0 | O6: 0 | P6: 0 | Q6: 0 | R6: 0 | S6: 0 | T6: 0 | U6: 0 | V6: 0 | W6: 0 | X6: 0 | Y6: 0 | Z6: 0 | AA6: =E6='Production Plan_wk33'!C342 -> TRUE
B7: GN7 2T HOD | D7: 657039500G | E7: =SUM(F7:Z7) -> 0 | F7: 0 | G7: 0 | H7: 0 | I7: 0 | J7: 0 | K7: 0 | L7: 0 | M7: 0 | N7: 0 | O7: 0 | P7: 0 | Q7: 0 | R7: 0 | S7: 0 | T7: 0 | U7: 0 | V7: 0 | W7: 0 | X7: 0 | Y7: 0 | Z7: 0 | AA7: =E7='Production Plan_wk33'!C343 -> TRUE
B8: GN7 FL 1T NH | D8: 669734000F | E8: =SUM(F8:Z8) -> 80 | F8: 0 | G8: 0 | H8: 80 | I8: 0 | J8: 0 | K8: 0 | L8: 0 | M8: 0 | N8: 0 | O8: 0 | P8: 0 | Q8: 0 | R8: 0 | S8: 0 | T8: 0 | U8: 0 | V8: 0 | W8: 0 | X8: 0 | Y8: 0 | Z8: 0 | AA8: =E8='Production Plan_wk33'!C344 -> TRUE
B9: GN7 FL 1T HOD | D9: 669734000F | E9: =SUM(F9:Z9) -> 1800 | F9: 0 | G9: 123 | H9: 166 | I9: 0 | J9: 123 | K9: 246 | L9: 0 | M9: 123 | N9: 246 | O9: 0 | P9: 0 | Q9: 0 | R9: 76 | S9: 123 | T9: 246 | U9: 82 | V9: 0 | W9: 246 | X9: 0 | Y9: 0 | Z9: 0 | AA9: =E9='Production Plan_wk33'!C345 -> TRUE
B10: GN7 FL 2T HOD | D10: 669586700F | E10: =SUM(F10:Z10) -> 774 | F10: 84 | G10: 72 | H10: 0 | I10: 105 | J10: 56 | K10: 0 | L10: 164 | M10: 82 | N10: 0 | O10: 0 | P10: 0 | Q10: 0 | R10: 88 | S10: 41 | T10: 0 | U10: 82 | V10: 0 | W10: 0 | X10: 0 | Y10: 0 | Z10: 0 | AA10: =E10='Production Plan_wk33'!C346 -> TRUE
B11: HG071 ( SP) | D11: 617233600B | E11: =SUM(F11:Z11) -> 0 | F11: 0 | G11: 0 | H11: 0 | I11: 0 | J11: 0 | K11: 0 | L11: 0 | M11: 0 | N11: 0 | O11: 0 | P11: 0 | Q11: 0 | R11: 0 | S11: 0 | T11: 0 | U11: 0 | V11: 0 | W11: 0 | X11: 0 | Y11: 0 | Z11: 0 | AA11: =E11='Production Plan_wk33'!C347 -> TRUE
B12: HG070 ( SP) | D12: 617233600B | E12: =SUM(F12:Z12) -> 0 | F12: 0 | G12: 0 | H12: 0 | I12: 0 | J12: 0 | K12: 0 | L12: 0 | M12: 0 | N12: 0 | O12: 0 | P12: 0 | Q12: 0 | R12: 0 | S12: 0 | T12: 0 | U12: 0 | V12: 0 | W12: 0 | X12: 0 | Y12: 0 | Z12: 0 | AA12: =E12='Production Plan_wk33'!C348 -> TRUE
B13: HG096 Heater | D13: 623059000A | E13: =SUM(F13:Z13) -> 0 | F13: 0 | G13: 0 | H13: 0 | I13: 0 | J13: 0 | K13: 0 | L13: 0 | M13: 0 | N13: 0 | O13: 0 | P13: 0 | Q13: 0 | R13: 0 | S13: 0 | T13: 0 | U13: 0 | V13: 0 | W13: 0 | X13: 0 | Y13: 0 | Z13: 0 | AA13: =E13='Production Plan_wk33'!C349 -> TRUE
B14: HG096 Non-heater | D14: 622034900B | E14: =SUM(F14:Z14) -> 0 | F14: 0 | G14: 0 | H14: 0 | I14: 0 | J14: 0 | K14: 0 | L14: 0 | M14: 0 | N14: 0 | O14: 0 | P14: 0 | Q14: 0 | R14: 0 | S14: 0 | T14: 0 | U14: 0 | V14: 0 | W14: 0 | X14: 0 | Y14: 0 | Z14: 0 | AA14: =E14='Production Plan_wk33'!C350 -> TRUE
B15: HG120 | D15: 629800500D | E15: =SUM(F15:Z15) -> 0 | F15: 0 | G15: 0 | H15: 0 | I15: 0 | J15: 0 | K15: 0 | L15: 0 | M15: 0 | N15: 0 | O15: 0 | P15: 0 | Q15: 0 | R15: 0 | S15: 0 | T15: 0 | U15: 0 | V15: 0 | W15: 0 | X15: 0 | Y15: 0 | Z15: 0 | AA15: =E15='Production Plan_wk33'!C351 -> TRUE
B16: HG180 Non-heater | D16: 656764500A | E16: =SUM(F16:Z16) -> 810 | F16: 135 | G16: 0 | H16: 135 | I16: 135 | J16: 0 | K16: 135 | L16: 135 | M16: 0 | N16: 135 | O16: 0 | P16: 0 | Q16: 0 | R16: 0 | S16: 0 | T16: 0 | U16: 0 | V16: 0 | W16: 0 | X16: 0 | Y16: 0 | Z16: 0 | AA16: =E16='Production Plan_wk33'!C352 -> TRUE
... B72: TN200 non-heater | D72: 657954900C | E72: =SUM(F72:Z72) -> 0 | F72: 0 | G72: 0 | H72: 0 | I72: 0 | J72: 0 | K72: 0 | L72: 0 | M72: 0 | N72: 0 | O72: 0 | P72: 0 | Q72: 0 | R72: 0 | S72: 0 | T72: 0 | U72: 0 | V72: 0 | W72: 0 | X72: 0 | Y72: 0 | Z72: 0 | AA72: =E72='Production Plan_wk33'!C408 -> TRUE
B73: TTL | E73: =SUM(E5:E72) -> 8520 | F73: =SUM(F5:F72) -> 1153 | G73: =SUM(G5:G72) -> 278 | H73: =SUM(H5:H72) -> 804 | I73: =SUM(I5:I72) -> 1092 | J73: =SUM(J5:J72) -> 278 | K73: =SUM(K5:K72) -> 804 | L73: =SUM(L5:L72) -> 1028 | ... Z73: =SUM(Z5:Z72) -> 0 | AA73: =E73='Production Plan_wk33'!C409 -> TRUE
B74: Daily output | F74: =SUM(F73:H73) -> 2235 | I74: =SUM(I73:K73) -> 2174 | L74: =SUM(L73:N73) -> 2110 | O74: =SUM(O73:Q73) -> 0 | R74: =SUM(R73:T73) -> 1435 | U74: =SUM(U73:W73) -> 566 | X74: =SUM(X73:Z73) -> 0
B77: Training AZP/ AMI | F77: =F2 -> 46237 | I77: =I2 -> 46238 | L77: =L2 -> 46239 | O77: =O2 -> 46240 | R77: =R2 -> 46241 | U77: =U2 -> 46242 | X77: =X2 -> 46243
B78: Model | D78: PU Body PN | E78: Rev. 0 | F78: Monday | I78: Tuesday | L78: Wednesday | O78: Thursday | R78: Friday | U78: Saturday | X78: Sunday
F79: 1st | G79: 2nd | H79: 3rd | I79: 1st | J79: 2nd | K79: 3rd | L79: 1st | M79: 2nd | N79: 3rd | O79: 1st | P79: 2nd | Q79: 3rd | R79: 1st | S79: 2nd | T79: 3rd | U79: 1st | V79: 2nd | W79: 3rd | X79: 1st | Y79: 2nd | Z79: 3rd
B80: MQ130 Non-Heater | D80: 630921700B | E80: =SUM(F80:Z80) -> 0 | F80: 0 | G80: 0 | H80: 0 | I80: 0 | J80: 0 | K80: 0 | L80: 0 | M80: 0 | N80: 0 | O80: 0 | P80: 0 | Q80: 0 | R80: 0 | S80: 0 | T80: 0 | U80: 0 | V80: 0 | W80: 0 | X80: 0 | Y80: 0 | Z80: 0 | AA80: =E80='Production Plan_wk33'!C416 -> TRUE
B81: MQ150 Heater | D81: 647618602A | E81: =SUM(F81:Z81) -> 0 | F81: 0 | G81: 0 | H81: 0 | I81: 0 | J81: 0 | K81: 0 | L81: 0 | M81: 0 | N81: 0 | O81: 0 | P81: 0 | Q81: 0 | R81: 0 | S81: 0 | T81: 0 | U81: 0 | V81: 0 | W81: 0 | X81: 0 | Y81: 0 | Z81: 0 | AA81: =E81='Production Plan_wk33'!C417 -> TRUE
B82: MQ150 NH | D82: 647528302A | E82: =SUM(F82:Z82) -> 0 | F82: 0 | G82: 0 | H82: 0 | I82: 0 | J82: 0 | K82: 0 | L82: 0 | M82: 0 | N82: 0 | O82: 0 | P82: 0 | Q82: 0 | R82: 0 | S82: 0 | T82: 0 | U82: 0 | V82: 0 | W82: 0 | X82: 0 | Y82: 0 | Z82: 0 | AA82: =E82='Production Plan_wk33'!C418 -> TRUE
B83: MQ170 Heater | D83: 654627600D | E83: =SUM(F83:Z83) -> 0 | F83: 0 | G83: 0 | H83: 0 | I83: 0 | J83: 0 | K83: 0 | L83: 0 | M83: 0 | N83: 0 | O83: 0 | P83: 0 | Q83: 0 | R83: 0 | S83: 0 | T83: 0 | U83: 0 | V83: 0 | W83: 0 | X83: 0 | Y83: 0 | Z83: 0 | AA83: =E83='Production Plan_wk33'!C419 -> TRUE
B84: MQ170 Non-Heater | D84: 654626800C | E84: =SUM(F84:Z84) -> 0 | F84: 0 | G84: 0 | H84: 0 | I84: 0 | J84: 0 | K84: 0 | L84: 0 | M84: 0 | N84: 0 | O84: 0 | P84: 0 | Q84: 0 | R84: 0 | S84: 0 | T84: 0 | U84: 0 | V84: 0 | W84: 0 | X84: 0 | Y84: 0 | Z84: 0 | AA84: =E84='Production Plan_wk33'!C420 -> TRUE
B85: HG180 NH | D85: 656764500A | E85: =SUM(F85:Z85) -> 0 | F85: 0 | G85: 0 | H85: 0 | I85: 0 | J85: 0 | K85: 0 | L85: 0 | M85: 0 | N85: 0 | O85: 0 | P85: 0 | Q85: 0 | R85: 0 | S85: 0 | T85: 0 | U85: 0 | V85: 0 | W85: 0 | X85: 0 | Y85: 0 | Z85: 0 | AA85: =E85='Production Plan_wk33'!C421 -> TRUE
B86: SA680 | D86: 631412000C | E86: =SUM(F86:Z86) -> 0 | F86: 0 | G86: 0 | H86: 0 | I86: 0 | J86: 0 | K86: 0 | L86: 0 | M86: 0 | N86: 0 | O86: 0 | P86: 0 | Q86: 0 | R86: 0 | S86: 0 | T86: 0 | U86: 0 | V86: 0 | W86: 0 | X86: 0 | Y86: 0 | Z86: 0 | AA86: =E86='Production Plan_wk33'!C422 -> TRUE
B87: TB655 NH | D87: 646033700A | E87: =SUM(F87:Z87) -> 0 | F87: 0 | G87: 0 | H87: 0 | I87: 0 | J87: 0 | K87: 0 | L87: 0 | M87: 0 | N87: 0 | O87: 0 | P87: 0 | Q87: 0 | R87: 0 | S87: 0 | T87: 0 | U87: 0 | V87: 0 | W87: 0 | X87: 0 | Y87: 0 | Z87: 0 | AA87: =E87='Production Plan_wk33'!C423 -> TRUE
B88: TB650 NH | D88: 634882300H | E88: =SUM(F88:Z88) -> 0 | F88: 0 | G88: 0 | H88: 0 | I88: 0 | J88: 0 | K88: 0 | L88: 0 | M88: 0 | N88: 0 | O88: 0 | P88: 0 | Q88: 0 | R88: 0 | S88: 0 | T88: 0 | U88: 0 | V88: 0 | W88: 0 | X88: 0 | Y88: 0 | Z88: 0 | AA88: =E88='Production Plan_wk33'!C424 -> TRUE
B89: TB670 NH Normal | D89: 648541200B | E89: =SUM(F89:Z89) -> 0 | F89: 0 | G89: 0 | H89: 0 | I89: 0 | J89: 0 | K89: 0 | L89: 0 | M89: 0 | N89: 0 | O89: 0 | P89: 0 | Q89: 0 | R89: 0 | S89: 0 | T89: 0 | U89: 0 | V89: 0 | W89: 0 | X89: 0 | Y89: 0 | Z89: 0 | AA89: =E89='Production Plan_wk33'!C425 -> TRUE
B90: TB670 Heater | D90: 648541902D | E90: =SUM(F90:Z90) -> 0 | F90: 0 | G90: 0 | H90: 0 | I90: 0 | J90: 0 | K90: 0 | L90: 0 | M90: 0 | N90: 0 | O90: 0 | P90: 0 | Q90: 0 | R90: 0 | S90: 0 | T90: 0 | U90: 0 | V90: 0 | W90: 0 | X90: 0 | Y90: 0 | Z90: 0 | AA90: =E90='Production Plan_wk33'!C426 -> TRUE
B91: TB667 Heater | D91: 670170000A | E91: =SUM(F91:Z91) -> 0 | F91: 0 | G91: 0 | H91: 0 | I91: 0 | J91: 0 | K91: 0 | L91: 0 | M91: 0 | N91: 0 | O91: 0 | P91: 0 | Q91: 0 | R91: 0 | S91: 0 | T91: 0 | U91: 0 | V91: 0 | W91: 0 | X91: 0 | Y91: 0 | Z91: 0 | AA91: =E91='Production Plan_wk33'!C427 -> TRUE
... B93: TB667 NH | D93: 670169600A | E93: =SUM(F93:Z93) -> 0 | F93: 0 | G93: 0 | H93: 0 | I93: 0 | J93: 0 | K93: 0 | L93: 0 | M93: 0 | N93: 0 | O93: 0 | P93: 0 | Q93: 0 | R93: 0 | S93: 0 | T93: 0 | U93: 0 | V93: 0 | W93: 0 | X93: 0 | Y93: 0 | Z93: 0 | AA93: =E93='Production Plan_wk33'!C429 -> TRUE
B94: TTL | E94: =SUM(E80:E93) -> 0 | F94: =SUM(F80:F93) -> 0 | G94: =SUM(G80:G93) -> 0 | H94: =SUM(H80:H93) -> 0 | I94: =SUM(I80:I93) -> 0 | J94: =SUM(J80:J93) -> 0 | K94: =SUM(K80:K93) -> 0 | L94: =SUM(L80:L93) -> 0 | ... Z94: =SUM(Z80:Z93) -> 0 | AA94: =E94='Production Plan_wk33'!C430 -> TRUE
B95: Daily output | F95: =SUM(F94:H94) -> 0 | I95: =SUM(I94:K94) -> 0 | L95: =SUM(L94:N94) -> 0 | O95: =SUM(O94:Q94) -> 0 | R95: =SUM(R94:T94) -> 0 | U95: =SUM(U94:W94) -> 0 | X95: =SUM(X94:Z94) -> 0
B97: TOTAL | G97: =F74+F95 -> 2235 | J97: =I74+I95 -> 2174 | M97: =L74+L95 -> 2110 | P97: =O74+O95 -> 0 | S97: =R74+R95 -> 1435 | V97: =U74+U95 -> 566 | Y97: =X74+X95 -> 0
G98: =G97 -> 2235 | J98: =J97+G98 -> 4409 | M98: =M97+J98 -> 6519 | P98: =P97+M98 -> 6519 | S98: =S97+P98 -> 7954 | V98: =V97+S98 -> 8520 | Y98: =Y97+V98 -> 8520
